Workbook

Sheet 범례·요약
A1: 표본 구성
A2: 표본 | B2: 정의 | C2: 이벤트 수
A3: Main | B3: 미국 제도화 이벤트 중 서프라이즈가 있고, 공개일 반응을 이벤트 효과로 볼 수 있는 표본. 본 가설 검정용 | C3: =COUNTIF('이벤트 리스트'!B2:B50,"Main") -> 22
A4: Robust | B4: 효과 분리가 어렵거나(매크로 일정 겹침), 예견된 이벤트, 비미국, 그리고 제도 이외의 이벤트(채택·기업·신뢰충격·정책지원). Main 결과 재확인과 대조 분석용 | C4: =COUNTIF('이벤트 리스트'!B2:B50,"Robust") -> 27
A5: 합계 | C5: =C3+C4 -> 49
A7: 카테고리별 개수
A8: 카테고리 | B8: 정의 | C8: Main | D8: Robust
A9: 입법 | B9: 의회의 법안 발의·위원회 표결·본회의 표결·대통령 서명 등 입법 절차의 한 단계 | C9: =COUNTIFS('이벤트 리스트'!$H$2:$H$50,A9,'이벤트 리스트'!$B$2:$B$50,"Main") -> 9 | D9: =COUNTIFS('이벤트 리스트'!$H$2:$H$50,A9,'이벤트 리스트'!$B$2:$B$50,"Robust") -> 1
A10: 규제 | B10: 감독·행정기관(SEC·OCC·CFTC·NYDFS·재무부·백악관)의 승인·해석·규칙·집행·행정명령 | C10: =COUNTIFS('이벤트 리스트'!$H$2:$H$50,A10,'이벤트 리스트'!$B$2:$B$50,"Main") -> 10 | D10: =COUNTIFS('이벤트 리스트'!$H$2:$H$50,A10,'이벤트 리스트'!$B$2:$B$50,"Robust") -> 13
A11: 사법 | B11: 법원 판결로 규제 적용 범위가 바뀐 경우 | C11: =COUNTIFS('이벤트 리스트'!$H$2:$H$50,A11,'이벤트 리스트'!$B$2:$B$50,"Main") -> 2 | D11: =COUNTIFS('이벤트 리스트'!$H$2:$H$50,A11,'이벤트 리스트'!$B$2:$B$50,"Robust") -> 0
A12: 채택 | B12: 민간 기업의 스테이블코인·토큰화 상품 출시나 도입 (제도 자체의 변화는 아님) | C12: =COUNTIFS('이벤트 리스트'!$H$2:$H$50,A12,'이벤트 리스트'!$B$2:$B$50,"Main") -> 0 | D12: =COUNTIFS('이벤트 리스트'!$H$2:$H$50,A12,'이벤트 리스트'!$B$2:$B$50,"Robust") -> 6
A13: 기업 | B13: 특정 기업의 상장·실적·신청 등 개별 기업 행위 | C13: =COUNTIFS('이벤트 리스트'!$H$2:$H$50,A13,'이벤트 리스트'!$B$2:$B$50,"Main") -> 1 | D13: =COUNTIFS('이벤트 리스트'!$H$2:$H$50,A13,'이벤트 리스트'!$B$2:$B$50,"Robust") -> 2
A14: 신뢰충격 | B14: 발행사·거래소 부실이나 디페깅 같은 시장 내부의 신용 사건 | C14: =COUNTIFS('이벤트 리스트'!$H$2:$H$50,A14,'이벤트 리스트'!$B$2:$B$50,"Main") -> 0 | D14: =COUNTIFS('이벤트 리스트'!$H$2:$H$50,A14,'이벤트 리스트'!$B$2:$B$50,"Robust") -> 4
A15: 정책지원 | B15: 금융안정을 위한 정부·중앙은행의 긴급 조치 | C15: =COUNTIFS('이벤트 리스트'!$H$2:$H$50,A15,'이벤트 리스트'!$B$2:$B$50,"Main") -> 0 | D15: =COUNTIFS('이벤트 리스트'!$H$2:$H$50,A15,'이벤트 리스트'!$B$2:$B$50,"Robust") -> 1
A16: 합계 | C16: =SUM(C9:C15) -> 22 | D16: =SUM(D9:D15) -> 27
B17: '사법'은 대시보드에 없던 카테고리로, 법원 판결 이벤트(Ripple, Grayscale)를 위해 새로 추가함
A19: 방향별 개수 (Main)
A20: 긍정 (+1) | C20: =COUNTIFS('이벤트 리스트'!$J$2:$J$50,1,'이벤트 리스트'!$B$2:$B$50,"Main") -> 16
A21: 중립 (0) | C21: =COUNTIFS('이벤트 리스트'!$J$2:$J$50,0,'이벤트 리스트'!$B$2:$B$50,"Main") -> 0
A22: 부정 (−1) | C22: =COUNTIFS('이벤트 리스트'!$J$2:$J$50,-1,'이벤트 리스트'!$B$2:$B$50,"Main") -> 6
A24: 열 설명
A25: 공개일(미 동부) | B25: 이벤트가 처음 공개된 미국 동부 기준 날짜
A26: 크립토 t0(UTC) | B26: 장 마감 후(16시 ET 이후) 공개된 이벤트는 다음 날로 설정. 크립토는 24시간 거래라 정확한 시각을 확인하면 더 좋음
A27: 미국 주식 t0 | B27: 장 마감 후 공개나 주말 공개는 다음 거래일. 미국 공휴일은 반영 안 됨 → 확인 필요
A28: 한국 주식 t0 | B28: 미국 이벤트는 한국 다음 영업일에 반영된다고 보고 계산. 한국 공휴일은 반영 안 됨 → 확인 필요
A29: 예견도 | B29: 높음: 일정이 미리 공개됨(표결·시행일) / 중간: 사전 보도 있음 / 낮음: 기습 발표
A30: 매크로 일정 겹침 | B30: 이벤트 전후 며칠 안에 있는 FOMC·CPI·선거 등. 매크로 변수 반응을 해석할 때 반드시 참고
A31: 클러스터 | B31: 같은 코드끼리는 날짜가 붙어 있어 하나의 이벤트로 취급하거나 함께 해석
A32: 출처 | B32: 빨간 글씨 "출처 링크 추가 필요"는 공식 링크를 아직 확인하지 못한 행
A33: 데이터 기준 | B33: 대시보드 이벤트(E01~E41)는 stablecoin_event_dashboard.html 기준. 2026년 이벤트 날짜는 2026-10-12에 웹 검색으로 확인

Sheet 이벤트 리스트
A1: 이벤트 ID | B1: 표본 | C1: 공개일(미 동부) | D1: 크립토 t0(UTC) | E1: 미국 주식 t0 | F1: 한국 주식 t0 | G1: 이벤트 | H1: 카테고리 | I1: 카테고리 사유 | J1: 방향(+1/0/−1) | K1: 예견도 | L1: 표본 사유 | M1: 매크로 일정 겹침 | N1: 클러스터 | O1: 대시보드 ID | P1: 비고 | Q1: 출처
A2: M01 | B2: Main | C2: 2019-04-25 | D2: 2019-04-26 | E2: 2019-04-26 | F2: 2019-04-26 | G2: 뉴욕 검찰, Bitfinex·Tether 자금 유용 소송 공개 | H2: 규제 | I2: 감독·행정기관(SEC·OCC·CFTC·NYDFS·재무부·백악관)의 승인·해석·규칙·집행·행정명령 — 주 검찰의 집행 조치 | J2: -1 | K2: 낮음 | L2: 예고 없던 집행 조치라 서프라이즈가 분명하고, 겹치는 매크로 일정이 없음 | M2: — | O2: E05 | P2: 장 마감 후 공개 → 미국 주식 t0는 4/26 | Q2: https://ag.ny.gov/press-release/2019/attorney-general-james-announces-court-order-against-crypto-currency-company
A3: M02 | B3: Main | C3: 2020-09-21 | D3: 2020-09-21 | E3: 2020-09-21 | F3: 2020-09-22 | G3: OCC, 은행의 스테이블코인 준비금 보관 허용(IL 1172) | H3: 규제 | I3: 감독·행정기관(SEC·OCC·CFTC·NYDFS·재무부·백악관)의 승인·해석·규칙·집행·행정명령 — 연방 은행감독기관의 해석서 | J3: 1 | K3: 낮음 | L3: 은행권의 스테이블코인 참여를 처음 허용한 해석. 서프라이즈가 있고 겹치는 매크로 일정이 없음 | M3: — | O3: E07 | Q3: https://www.occ.gov/news-issuances/news-releases/2020/nr-occ-2020-125.html
A4: M03 | B4: Main | C4: 2021-01-04 | D4: 2021-01-04 | E4: 2021-01-04 | F4: 2021-01-05 | G4: OCC, 은행의 스테이블코인 결제 활용 허용(IL 1174) | H4: 규제 | I4: 감독·행정기관(SEC·OCC·CFTC·NYDFS·재무부·백악관)의 승인·해석·규칙·집행·행정명령 — 연방 은행감독기관의 해석서 | J4: 1 | K4: 낮음 | L4: 은행의 스테이블코인 결제망 활용을 허용. 서프라이즈 있음 | M4: 조지아 결선투표 1/5(T+1) | O4: E08 | P4: BTC 강세장 한복판이라 비정상수익률 모형이 꼭 필요함 | Q4: https://www.occ.gov/news-issuances/news-releases/2021/nr-occ-2021-2.html
A5: M04 | B5: Main | C5: 2021-10-15 | D5: 2021-10-15 | E5: 2021-10-15 | F5: 2021-10-18 | G5: SEC, 첫 BTC 선물 ETF(BITO) 허용 보도 | H5: 규제 | I5: 감독·행정기관(SEC·OCC·CFTC·NYDFS·재무부·백악관)의 승인·해석·규칙·집행·행정명령 — SEC의 ETF 허용 결정 | J5: 1 | K5: 중간 | L5: 제도권 투자상품 접근을 처음 연 이벤트. 같은 날 CFTC Tether 제재(E11)보다 시장 영향이 훨씬 커서 이 날짜는 ETF 이벤트로 코딩 | M5: — | N5: C-2110 | O5: 신규(E11 대체) | P5: BTC +7.5%는 ETF 뉴스에 대한 반응 | Q5: 출처 링크 추가 필요
A6: M05 | B6: Main | C6: 2023-02-13 | D6: 2023-02-13 | E6: 2023-02-13 | F6: 2023-02-14 | G6: Paxos, NYDFS 명령으로 BUSD 신규 발행 중단 | H6: 규제 | I6: 감독·행정기관(SEC·OCC·CFTC·NYDFS·재무부·백악관)의 승인·해석·규칙·집행·행정명령 — NYDFS의 발행 중단 명령 | J6: -1 | K6: 낮음 | L6: 스테이블코인 발행사에 대한 직접 규제 조치이고 서프라이즈가 큼 | M6: CPI 2/14(T+1) | O6: E15 | P6: SEC 웰스노티스 보도는 2/12(일) → 크립토 t0를 2/12로 둔 민감도 분석 권장 | Q6: https://www.paxos.com/newsroom/paxos-will-halt-minting-new-busd-tokens
A7: M06 | B7: Main | C7: 2023-06-05 | D7: 2023-06-05 | E7: 2023-06-05 | F7: 2023-06-06 | G7: SEC, Binance(6/5)·Coinbase(6/6) 제소 | H7: 규제 | I7: 감독·행정기관(SEC·OCC·CFTC·NYDFS·재무부·백악관)의 승인·해석·규칙·집행·행정명령 — SEC의 집행(소송) 조치 | J7: -1 | K7: 낮음 | L7: 미국 최대 거래소들에 대한 집행 조치라 서프라이즈가 크고, 제도 후퇴 이벤트 표본을 보강함 | M7: CPI 6/13·FOMC 6/14가 [0,+5]에 걸림 | N7: C-2306a | O7: 신규 | P7: 이틀 연속이라 하나의 클러스터로 처리, [−1,+2]까지만 사용 권장 | Q7: https://www.sec.gov/newsroom/press-releases/2023-101
A8: M07 | B8: Main | C8: 2023-06-15 | D8: 2023-06-15 | E8: 2023-06-15 | F8: 2023-06-16 | G8: BlackRock, 현물 BTC ETF 신청 | H8: 기업 | I8: 특정 기업의 상장·실적·신청 등 개별 기업 행위 — 규제기관 결정이 아니라 운용사의 신청서 제출 | J8: 1 | K8: 낮음 | L8: 기업 행위지만 제도권 편입 기대를 급격히 바꾼 서프라이즈라 Main에 포함. 실제 승인(2024-01-10)과는 별개 이벤트 | M8: FOMC 6/14(T−1) | N8: C-2306b | O8: 신규 | Q8: 출처 링크 추가 필요
A9: M08 | B9: Main | C9: 2023-07-13 | D9: 2023-07-13 | E9: 2023-07-13 | F9: 2023-07-14 | G9: SEC v. Ripple 1심, 거래소 판매분은 증권 아님 판결 | H9: 사법 | I9: 법원 판결로 규제 적용 범위가 바뀐 경우 — 연방법원 판결 | J9: 1 | K9: 낮음 | L9: 증권성 판단이라는 규제 범위를 법원이 바꾼 서프라이즈 이벤트 | M9: CPI 7/12(T−1) | O9: 신규 | Q9: 출처 링크 추가 필요
A10: M09 | B10: Main | C10: 2023-08-29 | D10: 2023-08-29 | E10: 2023-08-29 | F10: 2023-08-30 | G10: Grayscale, SEC 상대 항소심 승소(현물 ETF 거부 위법) | H10: 사법 | I10: 법원 판결로 규제 적용 범위가 바뀐 경우 — 연방항소법원 판결 | J10: 1 | K10: 낮음 | L10: 현물 ETF 승인의 길을 연 판결. 매크로 오염이 가장 적은 깨끗한 표본 | M10: — | O10: 신규 | Q10: 출처 링크 추가 필요
A11: M10 | B11: Main | C11: 2024-01-10 | D11: 2024-01-11 | E11: 2024-01-11 | F11: 2024-01-11 | G11: SEC, 현물 BTC ETF 11종 승인 | H11: 규제 | I11: 감독·행정기관(SEC·OCC·CFTC·NYDFS·재무부·백악관)의 승인·해석·규칙·집행·행정명령 — SEC의 ETF 승인 | J11: 1 | K11: 높음 | L11: 미국 크립토 제도화의 대표 이벤트라 빼면 안 됨. 예견도가 높아 사전 반영(drift) 분석이 핵심 | M11: CPI 1/11 = 미국 주식 t0 당일 | O11: 신규 | P11: 장 마감 후 승인. 1/9 SEC 계정 해킹으로 허위 승인 트윗 → [−1] 구간 해석 주의 | Q11: https://www.sec.gov/newsroom/speeches-statements/gensler-statement-spot-bitcoin-011023
A12: M11 | B12: Main | C12: 2024-05-20 | D12: 2024-05-20 | E12: 2024-05-20 | F12: 2024-05-21 | G12: ETH 현물 ETF 승인 확률 급등(5/23 19b-4 승인) | H12: 규제 | I12: 감독·행정기관(SEC·OCC·CFTC·NYDFS·재무부·백악관)의 승인·해석·규칙·집행·행정명령 — SEC의 ETF 승인 | J12: 1 | K12: 낮음 | L12: ETH 제도화의 대표 이벤트. 5/20 SEC 태도 변화 보도가 실제 서프라이즈였음 | M12: FIT21 하원 통과 5/22 | N12: C-2405 | O12: 신규 | P12: 공식 승인은 5/23(장 마감 후). 둘 다 기록하고 5/20을 메인 t0로 | Q12: https://www.sec.gov/files/rules/sro/nysearca/2024/34-100224.pdf
A13: M12 | B13: Main | C13: 2025-01-23 | D13: 2025-01-24 | E13: 2025-01-24 | F13: 2025-01-24 | G13: SEC SAB 122(SAB 121 폐지) + 디지털자산 행정명령 | H13: 규제 | I13: 감독·행정기관(SEC·OCC·CFTC·NYDFS·재무부·백악관)의 승인·해석·규칙·집행·행정명령 — SEC 회계지침 폐지 + 대통령 행정명령 | J13: 1 | K13: 중간 | L13: 은행·기업의 가상자산 수탁 회계 부담을 없앤 조치라 기업 대응전략과 직접 연결됨 | M13: — | O13: 신규 | Q13: https://www.sec.gov/rules-regulations/staff-guidance/staff-accounting-bulletins/staff-accounting-bulletin-122
A14: M13 | B14: Main | C14: 2025-02-04 | D14: 2025-02-04 | E14: 2025-02-04 | F14: 2025-02-05 | G14: GENIUS Act 상원 발의 | H14: 입법 | I14: 의회의 법안 발의·위원회 표결·본회의 표결·대통령 서명 등 입법 절차의 한 단계 | J14: 1 | K14: 중간 | L14: 스테이블코인 법안이 공식 절차에 들어간 첫 단계 | M14: 관세 발표·유예(2/1~2/3) | O14: E23 | Q14: https://www.banking.senate.gov/newsroom/majority/scott-colleagues-pave-the-way-for-historic-digital-asset-legislation
A15: M14 | B15: Main | C15: 2025-03-06 | D15: 2025-03-07 | E15: 2025-03-07 | F15: 2025-03-07 | G15: 전략적 비트코인 비축 행정명령(+3/7 OCC IL 1183·백악관 서밋) | H15: 규제 | I15: 감독·행정기관(SEC·OCC·CFTC·NYDFS·재무부·백악관)의 승인·해석·규칙·집행·행정명령 — 대통령 행정명령 + OCC 해석서 | J15: 1 | K15: 중간 | L15: 국가 차원의 BTC 보유를 공식화한 이벤트 | M15: 관세 3/4 | N15: C-2503 | O15: 신규 | P15: 3/2(일) 트럼프 SNS 비축 언급이 실제 서프라이즈 → 3/2를 별도 t0로 민감도 분석 | Q15: https://www.whitehouse.gov/presidential-actions/2025/03/establishment-of-the-strategic-bitcoin-reserve-and-united-states-digital-asset-stockpile/
A16: M15 | B16: Main | C16: 2025-03-13 | D16: 2025-03-13 | E16: 2025-03-13 | F16: 2025-03-14 | G16: GENIUS Act 상원 은행위 통과(18-6) | H16: 입법 | I16: 의회의 법안 발의·위원회 표결·본회의 표결·대통령 서명 등 입법 절차의 한 단계 | J16: 1 | K16: 높음 | L16: 초당적 표차로 통과 가능성을 높인 단계 | M16: CPI 3/12(T−1) | O16: E24 | Q16: https://www.banking.senate.gov/newsroom/majority/scott-advances-stablecoin-debanking-legislation-out-of-banking-committee
A17: M16 | B17: Main | C17: 2025-05-08 | D17: 2025-05-08 | E17: 2025-05-08 | F17: 2025-05-09 | G17: GENIUS Act 상원 절차표결 부결 | H17: 입법 | I17: 의회의 법안 발의·위원회 표결·본회의 표결·대통령 서명 등 입법 절차의 한 단계 | J17: -1 | K17: 중간 | L17: 제도 후퇴 표본이 적어서 오염이 있어도 포함 | M17: FOMC 5/7(T−1), 미·영 무역합의 5/8 | O17: E25 | P17: 부정 이벤트인데 BTC +6.4%. 결과 해석 시 오염을 반드시 따로 언급 | Q17: https://www.senate.gov/legislative/LIS/roll_call_votes/vote1191/vote_119_1_00240.htm
A18: M17 | B18: Main | C18: 2025-06-10 | D18: 2025-06-10 | E18: 2025-06-10 | F18: 2025-06-11 | G18: CLARITY Act 하원 금융서비스위 통과 | H18: 입법 | I18: 의회의 법안 발의·위원회 표결·본회의 표결·대통령 서명 등 입법 절차의 한 단계 | J18: 1 | K18: 높음 | L18: 시장구조 법안의 첫 위원회 통과 | M18: CPI 6/11(T+1) | O18: E29 | Q18: https://docs.house.gov/Committee/Calendar/ByEvent.aspx?EventID=118373
A19: M18 | B19: Main | C19: 2025-06-17 | D19: 2025-06-18 | E19: 2025-06-18 | F19: 2025-06-18 | G19: GENIUS Act 상원 본회의 통과(68-30) | H19: 입법 | I19: 의회의 법안 발의·위원회 표결·본회의 표결·대통령 서명 등 입법 절차의 한 단계 | J19: 1 | K19: 높음 | L19: 스테이블코인 법의 핵심 관문이라 제외할 수 없음 | M19: FOMC 6/18 = 미국 주식 t0 당일, 이스라엘-이란 충돌 | O19: E30 | P19: 매크로 변수 반응은 FOMC와 분리 불가. 크립토 [−1,0]만 사용 권장 | Q19: https://www.booker.senate.gov/news/press/booker-statement-on-passage-of-genius-act
A20: M19 | B20: Main | C20: 2025-07-17 | D20: 2025-07-17 | E20: 2025-07-17 | F20: 2025-07-18 | G20: GENIUS·CLARITY 하원 통과 → 7/18 대통령 서명 | H20: 입법 | I20: 의회의 법안 발의·위원회 표결·본회의 표결·대통령 서명 등 입법 절차의 한 단계 | J20: 1 | K20: 높음 | L20: GENIUS 법률 제정 완료 시점. 하루 간격이라 두 이벤트를 병합 | M20: CPI 7/15(T−2) | N20: C-2507 | O20: E31+E32 | P20: '크립토 위크'(7/14~) 전체가 사전 반영 구간 | Q20: https://www.whitehouse.gov/fact-sheets/2025/07/fact-sheet-president-donald-j-trump-signs-genius-act-into-law/
A21: M20 | B21: Main | C21: 2026-01-14 | D21: 2026-01-15 | E21: 2026-01-15 | F21: 2026-01-15 | G21: CLARITY Act 상원 은행위 마크업 연기(Coinbase 지지 철회) | H21: 입법 | I21: 의회의 법안 발의·위원회 표결·본회의 표결·대통령 서명 등 입법 절차의 한 단계 | J21: -1 | K21: 낮음 | L21: 예고 없던 입법 차질이라 서프라이즈 큼. 제도 후퇴 표본 | M21: CPI 1/13(T−1) | O21: E34 | Q21: https://www.banking.senate.gov/newsroom/majority/scott-statement-on-market-structure-markup
A22: M21 | B22: Main | C22: 2026-05-14 | D22: 2026-05-14 | E22: 2026-05-14 | F22: 2026-05-15 | G22: CLARITY Act 상원 은행위 통과(15-9) | H22: 입법 | I22: 의회의 법안 발의·위원회 표결·본회의 표결·대통령 서명 등 입법 절차의 한 단계 | J22: 1 | K22: 높음 | L22: 시장구조 법안의 상원 첫 관문. 5/12 법안 공개는 CPI 발표일과 겹쳐 병합 | M22: CPI 5/12(T−2) | N22: C-2605 | O22: E38+E39 | Q22: https://www.cramer.senate.gov/news/press-releases/senate-banking-committee-passes-clarity-act
A23: M22 | B23: Main | C23: 2026-09-15 | D23: 2026-09-15 | E23: 2026-09-15 | F23: 2026-09-16 | G23: CLARITY Act 상원 절차표결 부결(49-50) | H23: 입법 | I23: 의회의 법안 발의·위원회 표결·본회의 표결·대통령 서명 등 입법 절차의 한 단계 | J23: -1 | K23: 중간 | L23: 가장 최근의 제도 후퇴 이벤트 | M23: FOMC 9/16(T+1) | O23: E41 | Q23: https://www.senate.gov/legislative/LIS/roll_call_votes/vote1192/vote_119_2_00234.htm
A24: R01 | B24: Robust | C24: 2017-12-01 | D24: 2017-12-01 | E24: 2017-12-01 | F24: 2017-12-04 | G24: CFTC, CME·Cboe BTC 선물 자기인증 허용 | H24: 규제 | I24: 감독·행정기관(SEC·OCC·CFTC·NYDFS·재무부·백악관)의 승인·해석·규칙·집행·행정명령 — CFTC의 파생상품 상장 허용 | J24: 1 | K24: 중간 | L24: 표본기간(2018~) 이전이고 BTC의 매크로 연동이 미미하던 시기. 2017년 국내 과열기 참고 표본 | M24: — | O24: 신규 | P24: 김치프리미엄 극단기 → 국내 전이 가설에서 참고 | Q24: https://www.cftc.gov/PressRoom/PressReleases/7654-17
A25: R02 | B25: Robust | C25: 2018-09-10 | D25: 2018-09-10 | E25: 2018-09-10 | F25: 2018-09-11 | G25: NYDFS, GUSD·PAX 스테이블코인 승인 | H25: 규제 | I25: 감독·행정기관(SEC·OCC·CFTC·NYDFS·재무부·백악관)의 승인·해석·규칙·집행·행정명령 — 주 감독기관의 발행 승인 | J25: 1 | K25: 낮음 | L25: 제도 이벤트지만 당시 스테이블코인 시장 규모가 작아 시장 반응을 기대하기 어려움 | M25: — | O25: E02 | Q25: https://www.gemini.com/blog/gemini-launches-the-gemini-dollar-us-dollars-on-the-blockchain
A26: R03 | B26: Robust | C26: 2018-09-26 | D26: 2018-09-26 | E26: 2018-09-26 | F26: 2018-09-27 | G26: Circle·CENTRE, USDC 출시 | H26: 채택 | I26: 민간 기업의 스테이블코인·토큰화 상품 출시나 도입 (제도 자체의 변화는 아님) | J26: 1 | K26: 높음 | L26: 민간 상품 출시이고 5월에 이미 계획이 발표돼 서프라이즈가 낮음 | M26: — | O26: E03 | Q26: https://www.circle.com/blog/introducing-usd-coin
A27: R04 | B27: Robust | C27: 2018-10-15 | D27: 2018-10-15 | E27: 2018-10-15 | F27: 2018-10-16 | G27: USDT 디페깅·신뢰 충격 | H27: 신뢰충격 | I27: 발행사·거래소 부실이나 디페깅 같은 시장 내부의 신용 사건 | J27: -1 | K27: 낮음 | L27: 제도 변화가 아니라 신용 사건 → 본 가설 검정에서 빼고 제도 이벤트와 반응을 비교하는 대조 분석용 | M27: — | O27: E04 | Q27: https://www.coindesk.com/markets/2018/10/15/price-of-stable-cryptocurrency-tether-tanks-to-18-month-low
A28: R05 | B28: Robust | C28: 2019-06-18 | D28: 2019-06-18 | E28: 2019-06-18 | F28: 2019-06-19 | G28: Facebook Libra 계획 공개 | H28: 채택 | I28: 민간 기업의 스테이블코인·토큰화 상품 출시나 도입 (제도 자체의 변화는 아님) | J28: 1 | K28: 중간 | L28: 민간 기업 계획 발표라 제도 이벤트가 아님 | M28: FOMC 6/19(T+1) | O28: E06 | Q28: https://about.fb.com/ja/news/2019/06/calibra_launch/
A29: R06 | B29: Robust | C29: 2021-02-23 | D29: 2021-02-23 | E29: 2021-02-23 | F29: 2021-02-24 | G29: 뉴욕 검찰·Tether 합의 | H29: 규제 | I29: 감독·행정기관(SEC·OCC·CFTC·NYDFS·재무부·백악관)의 승인·해석·규칙·집행·행정명령 — 주 검찰과의 합의 | J29: 0 | K29: 중간 | L29: 제도 이벤트지만 같은 날 매크로 발언 충격이 커서 효과를 분리할 수 없음 | M29: 옐런 발언 2/22, 파월 의회증언 2/23 | O29: E09 | P29: BTC −9.9%는 합의가 아니라 매크로·밸류에이션 발언 영향 | Q29: https://ag.ny.gov/press-release/2021/attorney-general-james-ends-virtual-currency-trading-platform-bitfinexs-illegal
A30: R07 | B30: Robust | C30: 2021-03-29 | D30: 2021-03-29 | E30: 2021-03-29 | F30: 2021-03-30 | G30: Visa, USDC 결제 정산 도입 | H30: 채택 | I30: 민간 기업의 스테이블코인·토큰화 상품 출시나 도입 (제도 자체의 변화는 아님) | J30: 1 | K30: 낮음 | L30: 민간 도입이라 제도 이벤트가 아님 | M30: — | O30: E10 | Q30: https://usa.visa.com/about-visa/newsroom/press-releases.releaseld.17821.html
A31: R08 | B31: Robust | C31: 2021-11-01 | D31: 2021-11-01 | E31: 2021-11-01 | F31: 2021-11-02 | G31: 대통령 금융시장 실무그룹 스테이블코인 보고서 | H31: 규제 | I31: 감독·행정기관(SEC·OCC·CFTC·NYDFS·재무부·백악관)의 승인·해석·규칙·집행·행정명령 — 재무부 주도 정부 보고서 | J31: 0 | K31: 중간 | L31: 권고안이라 구속력이 없고, 이틀 뒤 FOMC 테이퍼링 발표와 겹침 | M31: FOMC 11/3(T+2) | O31: E12 | P31: '발행은 은행만' 권고 → 방향 −1로 재코딩 검토 | Q31: https://home.treasury.gov/news/press-releases/jy0454
A32: R09 | B32: Robust | C32: 2022-05-09 | D32: 2022-05-09 | E32: 2022-05-09 | F32: 2022-05-10 | G32: TerraUSD(UST) 디페깅·런 | H32: 신뢰충격 | I32: 발행사·거래소 부실이나 디페깅 같은 시장 내부의 신용 사건 | J32: -1 | K32: 낮음 | L32: 제도 변화가 아니라 신용 사건 → 대조 분석용. 발행사가 한국계라 국내 전이 분석의 핵심 사례 | M32: FOMC 5/4, CPI 5/11 | O32: E13 | Q32: https://libertystreeteconomics.newyorkfed.org/2023/07/runs-on-stablecoins/
A33: R10 | B33: Robust | C33: 2022-06-08 | D33: 2022-06-08 | E33: 2022-06-08 | F33: 2022-06-09 | G33: NYDFS 달러 스테이블코인 준비금·상환 지침 | H33: 규제 | I33: 감독·행정기관(SEC·OCC·CFTC·NYDFS·재무부·백악관)의 승인·해석·규칙·집행·행정명령 — 주 감독기관의 지침 | J33: 1 | K33: 중간 | L33: 제도 이벤트지만 이틀 뒤 CPI 쇼크, Celsius 사태, 75bp 인상이 연달아 있어 효과를 분리할 수 없음 | M33: CPI 6/10, Celsius 인출중단 6/12, FOMC 6/15 | O33: E14 | P33: [0,+1]만 사용. d5의 BTC −28%는 매크로·Celsius 영향 | Q33: https://www.dfs.ny.gov/industry_guidance/industry_letters/il20220608_issuance_stablecoins
A34: R11 | B34: Robust | C34: 2022-11-08 | D34: 2022-11-08 | E34: 2022-11-08 | F34: 2022-11-09 | G34: FTX 유동성 위기(11/8) → 파산(11/11) | H34: 신뢰충격 | I34: 발행사·거래소 부실이나 디페깅 같은 시장 내부의 신용 사건 | J34: -1 | K34: 낮음 | L34: 제도 변화가 아니라 신용 사건 → 대조 분석용 | M34: 미 중간선거 11/8, CPI 11/10(나스닥 +7%) | O34: 신규 | P34: CPI 쇼크와 정면으로 겹침 → 매크로 변수는 [−1,+1]만 | Q34: 출처 링크 추가 필요
A35: R12 | B35: Robust | C35: 2023-03-10 | D35: 2023-03-11 | E35: 2023-03-13 | F35: 2023-03-13 | G35: SVB 파산·Circle 준비금 노출 → USDC 디페깅 | H35: 신뢰충격 | I35: 발행사·거래소 부실이나 디페깅 같은 시장 내부의 신용 사건 | J35: -1 | K35: 낮음 | L35: 제도 변화가 아니라 신용 사건이고 은행 위기라는 매크로 충격 자체 → 대조 분석용 | M35: SVB 자체가 매크로 금융 충격 | N35: C-2303 | O35: E16 | P35: 3/12 예금 전액 보호(E17)와 하나의 클러스터. 주식 t0는 3/13 | Q35: https://www.federalreserve.gov/econres/notes/feds-notes/in-the-shadow-of-bank-run-lessons-from-the-silicon-valley-bank-failure-and-its-impact-on-stablecoins-20251217.html
A36: R13 | B36: Robust | C36: 2023-03-12 | D36: 2023-03-12 | E36: 2023-03-13 | F36: 2023-03-13 | G36: 미 당국, SVB 예금 전액 보호·BTFP 발표 | H36: 정책지원 | I36: 금융안정을 위한 정부·중앙은행의 긴급 조치 | J36: 1 | K36: 낮음 | L36: 크립토 제도가 아니라 금융안정 조치 → 대조 분석용 | M36: — | N36: C-2303 | O36: E17 | P36: E16과 클러스터, 일요일 발표 → 주식 t0는 3/13 | Q36: https://www.federalreserve.gov/newsevents/pressreleases/monetary20230312b.htm
A37: R14 | B37: Robust | C37: 2023-08-07 | D37: 2023-08-07 | E37: 2023-08-07 | F37: 2023-08-08 | G37: PayPal PYUSD 출시 | H37: 채택 | I37: 민간 기업의 스테이블코인·토큰화 상품 출시나 도입 (제도 자체의 변화는 아님) | J37: 1 | K37: 낮음 | L37: 민간 상품 출시라 제도 이벤트가 아님 | M37: CPI 8/10(T+3) | O37: E18 | Q37: https://newsroom.paypal-corp.com/2023-08-07-PayPal-Launches-U-S-Dollar-Stablecoin
A38: R15 | B38: Robust | C38: 2024-03-20 | D38: 2024-03-20 | E38: 2024-03-20 | F38: 2024-03-21 | G38: BlackRock 토큰화 MMF BUIDL 출시 | H38: 채택 | I38: 민간 기업의 스테이블코인·토큰화 상품 출시나 도입 (제도 자체의 변화는 아님) | J38: 1 | K38: 중간 | L38: 민간 상품 출시. Part 2(RWA/STO)와 연결하려고 추가 | M38: FOMC 3/20 당일 | O38: 신규 | Q38: 출처 링크 추가 필요
A39: R16 | B39: Robust | C39: 2024-06-30 | D39: 2024-06-30 | E39: 2024-07-01 | F39: 2024-07-01 | G39: EU MiCA 스테이블코인 조항 적용 | H39: 규제 | I39: 감독·행정기관(SEC·OCC·CFTC·NYDFS·재무부·백악관)의 승인·해석·규칙·집행·행정명령 — EU 규정 시행 | J39: 1 | K39: 높음 | L39: 미국 이벤트가 아니고 시행일이 오래전부터 정해져 있었음 → 비미국 비교용 | M39: — | O39: E21 | P39: 일요일 → 주식 t0는 7/1 | Q39: https://www.eba.europa.eu/sites/default/files/2024-07/7dcd9ce9-96e3-4c5c-8d86-39d7784d1f03/EBA%20statement%20on%20Application%20of%20MiCAR%20to%20ARTs%20and%20EMTs.pdf
A40: R17 | B40: Robust | C40: 2024-07-23 | D40: 2024-07-23 | E40: 2024-07-23 | F40: 2024-07-24 | G40: ETH 현물 ETF 거래 개시 | H40: 채택 | I40: 민간 기업의 스테이블코인·토큰화 상품 출시나 도입 (제도 자체의 변화는 아님) — 승인(5/23)은 규제 이벤트, 거래 개시는 상품 출시 | J40: 1 | K40: 높음 | L40: 날짜가 미리 정해져 있었음. 승인일 대비 'sell the news' 확인용 | M40: — | O40: 신규 | Q40: 출처 링크 추가 필요
...

Sheet 변경 기록
A1: 구분 | B1: 대시보드 ID | C1: 날짜 | D1: 이벤트 | E1: 기존 카테고리 | F1: 최종 카테고리 | G1: 기존 방향 | H1: 최종 방향 | I1: 최종 표본 | J1: 최종 이벤트 ID | K1: 변경 사유
A2: 유지 | B2: E03 | C2: 2018-09-26 | D2: Circle USDC 출시 | E2: 채택 | F2: 채택 | G2: 1 | H2: 1 | I2: Robust | J2: R03 | K2: Robust 배정: 민간 상품 출시이고 5월에 이미 계획이 발표돼 서프라이즈가 낮음
A3: 유지 | B3: E04 | C3: 2018-10-15 | D3: USDT 신뢰 충격·디페깅 | E3: 신뢰충격 | F3: 신뢰충격 | G3: -1 | H3: -1 | I3: Robust | J3: R04 | K3: Robust 배정: 제도 변화가 아니라 신용 사건 → 본 가설 검정에서 빼고 제도 이벤트와 반응을 비교하는 대조 분석용
A4: 유지 | B4: E05 | C4: 2019-04-25 | D4: 뉴욕 검찰 Bitfinex·Tether 자금 문제 공개 | E4: 규제 | F4: 규제 | G4: -1 | H4: -1 | I4: Main | J4: M01 | K4: Main 배정: 예고 없던 집행 조치라 서프라이즈가 분명하고, 겹치는 매크로 일정이 없음
A5: 유지 | B5: E06 | C5: 2019-06-18 | D5: Facebook Libra 계획 공개 | E5: 채택 | F5: 채택 | G5: 1 | H5: 1 | I5: Robust | J5: R05 | K5: Robust 배정: 민간 기업 계획 발표라 제도 이벤트가 아님
A6: 유지 | B6: E07 | C6: 2020-09-21 | D6: OCC 은행의 스테이블코인 준비금 보관 허용 해석 | E6: 규제 | F6: 규제 | G6: 1 | H6: 1 | I6: Main | J6: M02 | K6: Main 배정: 은행권의 스테이블코인 참여를 처음 허용한 해석. 서프라이즈가 있고 겹치는 매크로 일정이 없음
A7: 유지 | B7: E08 | C7: 2021-01-04 | D7: OCC 은행의 스테이블코인 결제 활용 허용 해석 | E7: 규제 | F7: 규제 | G7: 1 | H7: 1 | I7: Main | J7: M03 | K7: Main 배정: 은행의 스테이블코인 결제망 활용을 허용. 서프라이즈 있음
A8: 유지 | B8: E09 | C8: 2021-02-23 | D8: 뉴욕 검찰·Tether 합의 발표 | E8: 규제 | F8: 규제 | G8: 0 | H8: 0 | I8: Robust | J8: R06 | K8: Robust 배정: 제도 이벤트지만 같은 날 매크로 발언 충격이 커서 효과를 분리할 수 없음
A9: 유지 | B9: E10 | C9: 2021-03-29 | D9: Visa USDC 결제 정산 시범 도입 | E9: 채택 | F9: 채택 | G9: 1 | H9: 1 | I9: Robust | J9: R07 | K9: Robust 배정: 민간 도입이라 제도 이벤트가 아님
A10: 유지 | B10: E12 | C10: 2021-11-01 | D10: 미 대통령 실무그룹 스테이블코인 보고서 | E10: 규제 | F10: 규제 | G10: 0 | H10: 0 | I10: Robust | J10: R08 | K10: Robust 배정: 권고안이라 구속력이 없고, 이틀 뒤 FOMC 테이퍼링 발표와 겹침
A11: 유지 | B11: E15 | C11: 2023-02-13 | D11: Paxos BUSD 신규 발행 중단 발표 | E11: 규제 | F11: 규제 | G11: -1 | H11: -1 | I11: Main | J11: M05 | K11: Main 배정: 스테이블코인 발행사에 대한 직접 규제 조치이고 서프라이즈가 큼
A12: 유지 | B12: E18 | C12: 2023-08-07 | D12: PayPal PYUSD 출시 | E12: 채택 | F12: 채택 | G12: 1 | H12: 1 | I12: Robust | J12: R14 | K12: Robust 배정: 민간 상품 출시라 제도 이벤트가 아님
A13: 유지 | B13: E23 | C13: 2025-02-04 | D13: GENIUS 초기 법안 발의 | E13: 입법 | F13: 입법 | G13: 1 | H13: 1 | I13: Main | J13: M13 | K13: Main 배정: 스테이블코인 법안이 공식 절차에 들어간 첫 단계
... A36: 병합 | B36: E39 | C36: 2026-05-14 | D36: CLARITY 상원 은행위 통과 | E36: 입법 | F36: 입법 | G36: 1 | H36: 1 | I36: Main | J36: M21 | K36: E38과 병합 / Main 배정: 시장구조 법안의 상원 첫 관문. 5/12 법안 공개는 CPI 발표일과 겹쳐 병합
A37: 추가 | B37: — | C37: 2017-12-01 | D37: CFTC, CME·Cboe BTC 선물 자기인증 허용 | E37: — | F37: 규제 | G37: — | H37: 1 | I37: Robust | J37: R01 | K37: 추가: 표본기간(2018~) 이전이고 BTC의 매크로 연동이 미미하던 시기. 2017년 국내 과열기 참고 표본
A38: 추가 | B38: — | C38: 2021-10-15 | D38: SEC, 첫 BTC 선물 ETF(BITO) 허용 보도 | E38: — | F38: 규제 | G38: — | H38: 1 | I38: Main | J38: M04 | K38: 추가(E11 대체): 제도권 투자상품 접근을 처음 연 이벤트. 같은 날 CFTC Tether 제재(E11)보다 시장 영향이 훨씬 커서 이 날짜는 ETF 이벤트로 코딩
A39: 추가 | B39: — | C39: 2022-11-08 | D39: FTX 유동성 위기(11/8) → 파산(11/11) | E39: — | F39: 신뢰충격 | G39: — | H39: -1 | I39: Robust | J39: R11 | K39: 추가: 제도 변화가 아니라 신용 사건 → 대조 분석용
A40: 추가 | B40: — | C40: 2023-06-05 | D40: SEC, Binance(6/5)·Coinbase(6/6) 제소 | E40: — | F40: 규제 | G40: — | H40: -1 | I40: Main | J40: M06 | K40: 추가: 미국 최대 거래소들에 대한 집행 조치라 서프라이즈가 크고, 제도 후퇴 이벤트 표본을 보강함
A41: 추가 | B41: — | C41: 2023-06-15 | D41: BlackRock, 현물 BTC ETF 신청 | E41: — | F41: 기업 | G41: — | H41: 1 | I41: Main | J41: M07 | K41: 추가: 기업 행위지만 제도권 편입 기대를 급격히 바꾼 서프라이즈라 Main에 포함. 실제 승인(2024-01-10)과는 별개 이벤트
A42: 추가 | B42: — | C42: 2023-07-13 | D42: SEC v. Ripple 1심, 거래소 판매분은 증권 아님 판결 | E42: — | F42: 사법 | G42: — | H42: 1 | I42: Main | J42: M08 | K42: 추가: 증권성 판단이라는 규제 범위를 법원이 바꾼 서프라이즈 이벤트
A43: 추가 | B43: — | C43: 2023-08-29 | D43: Grayscale, SEC 상대 항소심 승소(현물 ETF 거부 위법) | E43: — | F43: 사법 | G43: — | H43: 1 | I43: Main | J43: M09 | K43: 추가: 현물 ETF 승인의 길을 연 판결. 매크로 오염이 가장 적은 깨끗한 표본
A44: 추가 | B44: — | C44: 2024-01-10 | D44: SEC, 현물 BTC ETF 11종 승인 | E44: — | F44: 규제 | G44: — | H44: 1 | I44: Main | J44: M10 | K44: 추가: 미국 크립토 제도화의 대표 이벤트라 빼면 안 됨. 예견도가 높아 사전 반영(drift) 분석이 핵심
A45: 추가 | B45: — | C45: 2024-03-20 | D45: BlackRock 토큰화 MMF BUIDL 출시 | E45: — | F45: 채택 | G45: — | H45: 1 | I45: Robust | J45: R15 | K45: 추가: 민간 상품 출시. Part 2(RWA/STO)와 연결하려고 추가
A46: 추가 | B46: — | C46: 2024-05-20 | D46: ETH 현물 ETF 승인 확률 급등(5/23 19b-4 승인) | E46: — | F46: 규제 | G46: — | H46: 1 | I46: Main | J46: M11 | K46: 추가: ETH 제도화의 대표 이벤트. 5/20 SEC 태도 변화 보도가 실제 서프라이즈였음
A47: 추가 | B47: — | C47: 2024-07-23 | D47: ETH 현물 ETF 거래 개시 | E47: — | F47: 채택 | G47: — | H47: 1 | I47: Robust | J47: R17 | K47: 추가: 날짜가 미리 정해져 있었음. 승인일 대비 'sell the news' 확인용
A48: 추가 | B48: — | C48: 2025-01-23 | D48: SEC SAB 122(SAB 121 폐지) + 디지털자산 행정명령 | E48: — | F48: 규제 | G48: — | H48: 1 | I48: Main | J48: M12 | K48: 추가: 은행·기업의 가상자산 수탁 회계 부담을 없앤 조치라 기업 대응전략과 직접 연결됨
... A53: 추가 | B53: — | C53: 2025-09-17 | D53: SEC, 현물 상품 ETF 일반상장기준 승인 | E53: — | F53: 규제 | G53: — | H53: 1 | I53: Robust | J53: R24 | K53: 추가: FOMC 금리 인하 발표일과 같은 날이라 효과를 분리할 수 없음
A54: 제외 | B54: E01 | C54: 2015-06-03 | D54: 뉴욕 BitLicense 최종 규정 발표 | E54: 규제 | F54: — | G54: 0 | H54: — | I54: — | J54: — | K54: 스테이블코인 시장 형성 이전(2015)이고 BTC의 매크로 연동이 미미하던 시기. 국내 비교 데이터도 없음
A55: 제외 | B55: E11 | C55: 2021-10-15 | D55: CFTC Tether 준비금 공시 관련 제재 | E55: 규제 | F55: — | G55: -1 | H55: — | I55: — | J55: — | K55: 같은 날 SEC의 BITO 선물 ETF 허용 보도(긍정)와 겹쳐 방향이 반대인 두 효과를 분리할 수 없음 → 이 날짜는 BITO 이벤트로 대체
A56: 제외 | B56: E19 | C56: 2023-09-05 | D56: Visa USDC 정산을 Solana로 확대 | E56: 채택 | F56: — | G56: 1 | H56: — | I56: — | J56: — | K56: 기존 Visa 정산 서비스의 체인 확대라 새로운 정보가 거의 없음
A57: 제외 | B57: E20 | C57: 2024-05-29 | D57: PYUSD Solana 네트워크 출시 | E57: 채택 | F57: — | G57: 1 | H57: — | I57: — | J57: — | K57: 기존 PYUSD의 체인 추가라 새로운 정보가 거의 없음
A58: 제외 | B58: E22 | C58: 2024-11-04 | D58: USDG Global Dollar Network 출범 | E58: 채택 | F58: — | G58: 1 | H58: — | I58: — | J58: — | K58: 하루 뒤 미국 대선(11/5), 3일 뒤 FOMC(11/7)와 겹쳐 효과를 식별할 수 없음
A59: 제외 | B59: E26 | C59: 2025-05-15 | D59: Mastercard·MoonPay 스테이블코인 결제 협력 | E59: 채택 | F59: — | G59: 1 | H59: — | I59: — | J59: — | K59: 제휴 발표 수준이라 시장 전체에 대한 정보가치가 낮음
A60: 검토 후 제외 | B60: — | C60: 2020-03-15 | D60: Fed 긴급 제로금리·QE 재개 | E60: — | F60: — | G60: — | H60: — | I60: — | J60: — | K60: 매크로 통제 이벤트로 검토했으나 팀 결정으로 이벤트 리스트에서 제외. 대신 각 이벤트의 '매크로 일정 겹침' 열로 오염 여부를 관리
A61: 검토 후 제외 | B61: — | C61: 2022-03-16 | D61: FOMC 첫 금리인상 | E61: — | F61: — | G61: — | H61: — | I61: — | J61: — | K61: 매크로 통제 이벤트로 검토했으나 팀 결정으로 이벤트 리스트에서 제외. 대신 각 이벤트의 '매크로 일정 겹침' 열로 오염 여부를 관리
A62: 검토 후 제외 | B62: — | C62: 2022-06-15 | D62: FOMC 75bp 인상 | E62: — | F62: — | G62: — | H62: — | I62: — | J62: — | K62: 매크로 통제 이벤트로 검토했으나 팀 결정으로 이벤트 리스트에서 제외. 대신 각 이벤트의 '매크로 일정 겹침' 열로 오염 여부를 관리
A63: 검토 후 제외 | B63: — | C63: 2022-09-13 | D63: CPI 상방 서프라이즈 | E63: — | F63: — | G63: — | H63: — | I63: — | J63: — | K63: 매크로 통제 이벤트로 검토했으나 팀 결정으로 이벤트 리스트에서 제외. 대신 각 이벤트의 '매크로 일정 겹침' 열로 오염 여부를 관리
A64: 검토 후 제외 | B64: — | C64: 2022-11-10 | D64: CPI 하방 서프라이즈 | E64: — | F64: — | G64: — | H64: — | I64: — | J64: — | K64: 매크로 통제 이벤트로 검토했으나 팀 결정으로 이벤트 리스트에서 제외. 대신 각 이벤트의 '매크로 일정 겹침' 열로 오염 여부를 관리
A65: 검토 후 제외 | B65: — | C65: 2024-09-18 | D65: FOMC 50bp 인하 | E65: — | F65: — | G65: — | H65: — | I65: — | J65: — | K65: 매크로 통제 이벤트로 검토했으나 팀 결정으로 이벤트 리스트에서 제외. 대신 각 이벤트의 '매크로 일정 겹침' 열로 오염 여부를 관리
A66: 검토 후 제외 | B66: — | C66: 2024-12-18 | D66: FOMC 매파적 인하 | E66: — | F66: — | G66: — | H66: — | I66: — | J66: — | K66: 매크로 통제 이벤트로 검토했으나 팀 결정으로 이벤트 리스트에서 제외. 대신 각 이벤트의 '매크로 일정 겹침' 열로 오염 여부를 관리
...
